Workbook

Sheet Deckblatt
A1: Schutzbedarfsanalyse
H3: Speichern Sie jede Schutzbedarfsanalyse einzeln für jedes schutzbedürftige Asset ab, um die Rückverfolgbarkeit zu gewährleisten. Erstellt mit KOPEXA Schutzbedarfsanalyse (schutzbedarf.kopexa.com).
A5: Schutzbedarfsfeststellung für | D5: Kunden-CRM
A7: Version: | D7: 1.0
A9: Status: | D9: abgeschlossen
A11: zuletzt bearbeitet am: | D11: 46295.372 | F11: von: | H11: Anna Beispiel
A12: fachlich freigegeben am: | F12: von:
A13: freigegeben am: | F13: von:
A15: Verantwortliche Organisationseinheit:
A16: Kontakt:
A18: personenbezogene Daten: | D18: ja | F18: besondere Art personenbezogener Daten: | I18: <bitte auswählen>
A20: Schutzbedarf Zusammenfassung | F20: Begründung
A21: Management Summary | C21: Vertraulichkeit | D21: =IF(Anwendung!E35<>"",Anwendung!E35,Anwendung!E1) -> Hoch | F21: Umfangreiche personenbezogene Kundendaten mit vertraglichen Vertraulichkeitspflichten.
C22: Integrität | D22: =IF(Anwendung!E72<>"",Anwendung!E72,Anwendung!E37) -> Normal
C23: Verfügbarkeit | D23: =IF(Anwendung!E109<>"",Anwendung!E109,Anwendung!E74) -> Sehr hoch | F23: Kernprozess Kundenservice ist vollständig vom CRM abhängig (RTO ≤ 1 h).
A25: Änderungshistorie
A26: Nr. | B26: Version | D26: Datum | F26: Beschreibung der Änderung | I26: Bearbeiter
A27: 1 | B27: 1.0 | D27: 46295.372 | F27: Ersterstellung | I27: Anna Beispiel
A28: 2
A29: 3
A30: 4
A31: 5
A32: 6
A33: 7
A34: 8
A35: 9
A36: 10
A39: Weitere Stammdaten
A40: Asset-Typ | D40: Anwendung
A41: Asset-Owner | D41: Leitung Vertrieb
A42: Ersteller:in der Analyse | D42: Informationssicherheit
A43: Beschreibung / Einsatzzweck
A44: Geltungsbereich | D44: Produktivsystem inkl. Schnittstellen zu ERP und Newsletter-Dienst
A45: Standort
A46: Asset-ID | D46: 01219b41-18c4-4af4-97f3-93ef3b9b06df
A47: Versions-ID | D47: e246a41b-8163-46c9-8155-ab1ec5df91d2
A48: Abgeschlossen | D48: 2026-09-30T08:55:05.833Z, Anna Beispiel
A49: Bewertungsschema | D49: Standard (Referenzbogen) (Stand 1): Finanzieller Schaden hoch ab 1.000.000 €, sehr hoch ab 10.000.000 €; tolerierbarer Ausfall hoch bis 24 Stunden, sehr hoch bis 1 Stunde.
A50: Organisation | D50: Musterstadtwerke GmbH
A51: Erstellt durch
...

Sheet Anwendung
B1: Grundwert Vertraulichkeit | E1: =IF(Hilfstabelle!B10=5,"Normal", IF(Hilfstabelle!B10>=1000,"Sehr hoch",IF(Hilfstabelle!B10>=10,"Hoch","Bitte Spalte E ausfüllen"))) -> Hoch
B2: Schadensszenario | D2: Frage | E2: Antwort | F2: weitere Ausführungen | G2: Schutzbedarf | H2: Erläuterung Schutzbedarf
B3: Verstoß gegen Gesetze, Vorschriften und Verträge | D3: Erfordern Gesetze, Vorschriften oder vertragliche Regelungen die Vertraulichkeit der Informationen? | E3: Ja | G3: =IF(AND(E5="Ja",E6="Ja",E7="Ja"),"Eingabe prüfen!",IF(AND(E5="Ja",E6="Ja"),"Eingabe prüfen!",IF(AND(E5="Ja",E7="Ja"),"Eingabe prüfen!",IF(AND(E6="Ja",E7="Ja"),"Eingabe prüfen!",IF(AND(E3="Nein",E5="Ja"),"Eingabe prüfen!",IF(AND(E3="Nein",E6="Ja"),"Eingabe prüfen!",IF(AND(E3="Nein",E7="Ja"),"Eingabe prüfen!",IF(AND(E3="Ja",E5="Nein",E6="Nein",E7="Nein"),"Eingabe prüfen!",IF(OR(E3="Nein",E5="Ja"),"Normal",IF(E6="Ja","Hoch",IF(E7="Ja","Sehr hoch"))))))))))) -> Hoch | H3: Vertraulichkeitsvereinbarungen mit Großkunden sehen Vertragsstrafen vor.
D4: Falls ja, führt die Kenntnisnahme der Informationen durch Unbefugte zu
D5: geringen Verstößen gegen diese Regelungen und damit zu geringfügigen juristischen Konsequenzen / Vertragsstrafen? | E5: Nein
D6: erheblichen Verstößen gegen diese Regelungen und damit zu erheblichen juristischen Konsequenzen / Vertragsstrafen? | E6: Ja
D7: fundamentalen Verstößen gegen diese Regelungen und damit zu massiven juristischen Konsequenzen / Vertragsstrafen? | E7: Nein
B9: Beeinträchtigung des informationellen Selbstbestimmungsrechts | D9: Erfolgt eine Verarbeitung von personenbezogenen Daten? | E9: Ja | G9: =IF(AND(E11="Ja",E12="Ja",E13="Ja"),"Eingabe prüfen!",IF(AND(E11="Ja",E12="Ja"),"Eingabe prüfen!",IF(AND(E11="Ja",E13="Ja"),"Eingabe prüfen!",IF(AND(E12="Ja",E13="Ja"),"Eingabe prüfen!",IF(AND(E9="Nein",E11="Ja"),"Eingabe prüfen!",IF(AND(E9="Nein",E12="Ja"),"Eingabe prüfen!",IF(AND(E9="Nein",E13="Ja"),"Eingabe prüfen!",IF(AND(E9="Ja",E11="Nein",E12="Nein",E13="Nein"),"Eingabe prüfen!",IF(OR(E9="Nein",E11="Ja"),"Normal",IF(E12="Ja","Hoch",IF(E13="Ja","Sehr hoch"))))))))))) -> Hoch | H9: Kontakt- und Vertragsdaten von ca. 120.000 Kund:innen; Meldepflicht nach Art. 33 DSGVO.
D10: Falls ja, hat die Kenntnisnahme der personenbezogenen Daten durch Unbefugte
D11: geringfügige Auswirkungen auf die Betroffenen und wird von diesen toleriert? | E11: Nein
D12: erhebliche Auswirkungen auf die Betroffenen und kann diese in ihrer gesellschaftlichen Stellung oder ihren wirtschaftlichen Verhältnissen erheblich beeinträchtigen? | E12: Ja
D13: fundamentale Auswirkungen auf die Betroffenen und kann für diese eine Gefahr für Leib und Leben oder die persönliche Freiheit darstellen? | E13: Nein
B15: Beeinträchtigung der persönlichen Unversehrtheit | D15: Eine Betrachtung dieses Szenarios beim Grundwert Vertraulichkeit ist nicht sinnvoll, da keine Unmittelbarkeit zwischen Vertraulichkeitsverlust und Beeinträchtigung denkbar ist.
B17: Beeinträchtigung der Aufgabenerfüllung | D17: Ist die Vertraulichkeit der Informationen Grundlage der Aufgabenerfüllung? | E17: Nein | G17: =IF(AND(E19="Ja",E20="Ja",E21="Ja"),"Eingabe prüfen!",IF(AND(E19="Ja",E20="Ja"),"Eingabe prüfen!",IF(AND(E19="Ja",E21="Ja"),"Eingabe prüfen!",IF(AND(E20="Ja",E21="Ja"),"Eingabe prüfen!",IF(AND(E17="Nein",E19="Ja"),"Eingabe prüfen!",IF(AND(E17="Nein",E20="Ja"),"Eingabe prüfen!",IF(AND(E17="Nein",E21="Ja"),"Eingabe prüfen!",IF(AND(E17="Ja",E19="Nein",E20="Nein",E21="Nein"),"Eingabe prüfen!",IF(OR(E17="Nein",E19="Ja"),"Normal",IF(E20="Ja","Hoch",IF(E21="Ja","Sehr hoch"))))))))))) -> Normal
D18: Falls ja, hat die Kenntnisnahme der Informationen durch Unbefugte
D19: geringfügige Auswirkungen auf die Aufgabenerfüllung und wird von diesen toleriert? | E19: Nein
D20: erhebliche Auswirkungen auf die Aufgabenerfüllung und wird von einzelnen Betroffenen als nicht tolerierbar eingeschätzt? | E20: Nein
D21: fundamentale Auswirkungen auf die Aufgabenerfüllung und wird von allen Betroffenen als nicht tolerierbar eingeschätzt? | E21: Nein
B23: Negative Innen- oder Außenwirkung | D23: Erfolgt eine Verarbeitung schutzbedürftiger Informationen? | E23: Nein | G23: =IF(AND(E25="Ja",E26="Ja",E27="Ja"),"Eingabe prüfen!",IF(AND(E25="Ja",E26="Ja"),"Eingabe prüfen!",IF(AND(E25="Ja",E27="Ja"),"Eingabe prüfen!",IF(AND(E26="Ja",E27="Ja"),"Eingabe prüfen!",IF(AND(E23="Nein",E25="Ja"),"Eingabe prüfen!",IF(AND(E23="Nein",E26="Ja"),"Eingabe prüfen!",IF(AND(E23="Nein",E27="Ja"),"Eingabe prüfen!",IF(AND(E23="Ja",E25="Nein",E26="Nein",E27="Nein"),"Eingabe prüfen!",IF(OR(E23="Nein",E25="Ja"),"Normal",IF(E26="Ja","Hoch",IF(E27="Ja","Sehr hoch"))))))))))) -> Normal
D24: Falls ja, führt die Kenntnisnahme der Informationen durch Unbefugte zu
D25: einer geringen bzw. nur ressortinternen Ansehens- / Vertrauensbeeinträchtigung? | E25: Nein
D26: einer erheblichen Ansehens- / Vertrauensbeeinträchtigung auch außerhalb des Ressorts? | E26: Nein
D27: einer dauerhaften Ansehens- / Vertrauensbeeinträchtigung außerhalb des Ressorts, ggf. sogar auf internationaler Ebene? | E27: Nein
B29: Finanzielle Auswirkungen | D29: Erfolgt eine Verarbeitung schutzbedürftiger Informationen? | E29: Nein | G29: =IF(AND(E31="Ja",E32="Ja",E33="Ja"),"Eingabe prüfen!",IF(AND(E31="Ja",E32="Ja"),"Eingabe prüfen!",IF(AND(E31="Ja",E33="Ja"),"Eingabe prüfen!",IF(AND(E32="Ja",E33="Ja"),"Eingabe prüfen!",IF(AND(E29="Nein",E31="Ja"),"Eingabe prüfen!",IF(AND(E29="Nein",E32="Ja"),"Eingabe prüfen!",IF(AND(E29="Nein",E33="Ja"),"Eingabe prüfen!",IF(AND(E29="Ja",E31="Nein",E32="Nein",E33="Nein"),"Eingabe prüfen!",IF(OR(E29="Nein",E31="Ja"),"Normal",IF(E32="Ja","Hoch",IF(E33="Ja","Sehr hoch"))))))))))) -> Normal
D30: Falls ja, führt die Kenntnisnahme der Informationen durch Unbefugte zu
D31: einem finanziellen Schaden von weniger als 1.000.000 €? | E31: Nein
D32: einem finanziellen Schaden von mehr als 1.000.000 €? | E32: Nein
D33: einem finanziellen Schaden von mehr als 10.000.000 €? | E33: Nein
B35: Manuelle Übersteuerung | D35: keine
B37: Grundwert Integrität | E37: =IF(Hilfstabelle!D10=6,"Normal", IF(Hilfstabelle!D10>=1000,"Sehr hoch",IF(Hilfstabelle!D10>=10,"Hoch","Bitte Spalte E ausfüllen"))) -> Normal
B38: Schadensszenario | D38: Frage | E38: Antwort | F38: weitere Ausführungen | G38: Schutzbedarf | H38: Erläuterung Schutzbedarf
B39: Verstoß gegen Gesetze, Vorschriften und Verträge | D39: Erfordern Gesetze, Vorschriften oder vertragliche Regelungen die Integrität der Informationen? | E39: Nein | G39: =IF(AND(E41="Ja",E42="Ja",E43="Ja"),"Eingabe prüfen!",IF(AND(E41="Ja",E42="Ja"),"Eingabe prüfen!",IF(AND(E41="Ja",E43="Ja"),"Eingabe prüfen!",IF(AND(E42="Ja",E43="Ja"),"Eingabe prüfen!",IF(AND(E39="Nein",E41="Ja"),"Eingabe prüfen!",IF(AND(E39="Nein",E42="Ja"),"Eingabe prüfen!",IF(AND(E39="Nein",E43="Ja"),"Eingabe prüfen!",IF(AND(E39="Ja",E41="Nein",E42="Nein",E43="Nein"),"Eingabe prüfen!",IF(OR(E39="Nein",E41="Ja"),"Normal",IF(E42="Ja","Hoch",IF(E43="Ja","Sehr hoch"))))))))))) -> Normal
D40: Falls ja, führt die Verfälschung/Manipulation der Informationen zu
D41: geringen Verstößen gegen diese Regelungen und damit zu geringfügigen juristischen Konsequenzen / Vertragsstrafen? | E41: Nein
D42: erheblichen Verstößen gegen diese Regelungen und damit zu erheblichen juristischen Konsequenzen / Vertragsstrafen? | E42: Nein
D43: fundamentalen Verstößen gegen diese Regelungen und damit zu massiven juristischen Konsequenzen / Vertragsstrafen? | E43: Nein
B45: Beeinträchtigung des informationellen Selbstbestimmungsrechts | D45: Erfolgt eine Verarbeitung von personenbezogenen Daten? | E45: Ja | G45: =IF(AND(E47="Ja",E48="Ja",E49="Ja"),"Eingabe prüfen!",IF(AND(E47="Ja",E48="Ja"),"Eingabe prüfen!",IF(AND(E47="Ja",E49="Ja"),"Eingabe prüfen!",IF(AND(E48="Ja",E49="Ja"),"Eingabe prüfen!",IF(AND(E45="Nein",E47="Ja"),"Eingabe prüfen!",IF(AND(E45="Nein",E48="Ja"),"Eingabe prüfen!",IF(AND(E45="Nein",E49="Ja"),"Eingabe prüfen!",IF(AND(E45="Ja",E47="Nein",E48="Nein",E49="Nein"),"Eingabe prüfen!",IF(OR(E45="Nein",E47="Ja"),"Normal",IF(E48="Ja","Hoch",IF(E49="Ja","Sehr hoch"))))))))))) -> Normal
D46: Falls ja, hat die Verfälschung/Manipulation der personenbezogenen Daten
D47: geringfügige Auswirkungen auf die Betroffenen und wird von diesen toleriert? | E47: Ja
D48: erhebliche Auswirkungen auf die Betroffenen und kann diese in ihrer gesellschaftlichen Stellung oder ihren wirtschaftlichen Verhältnissen erheblich beeinträchtigen? | E48: Nein
...

Sheet Audit-Trail
A1: Zeitstempel (UTC) | B1: Version | C1: Akteur | D1: Aktion | E1: Feld / Kriterium | F1: Alter Wert | G1: Neuer Wert | H1: Änderungsgrund
A2: 2026-09-30T08:55:00.130Z | B2: 1.0-dev | C2: Anna Beispiel | D2: Angelegt | G2: 1.0-dev
A3: 2026-09-30T08:55:00.204Z | B3: 1.0-dev | C3: Anna Beispiel | D3: Geändert | E3: Asset-Owner | G3: Leitung Vertrieb
A4: 2026-09-30T08:55:00.214Z | B4: 1.0-dev | C4: Anna Beispiel | D4: Geändert | E4: Ersteller:in | G4: Informationssicherheit
A5: 2026-09-30T08:55:00.219Z | B5: 1.0-dev | C5: Anna Beispiel | D5: Geändert | E5: Geltungsbereich | G5: Produktivsystem inkl. Schnittstellen zu ERP und Newsletter-Dienst
A6: 2026-09-30T08:55:00.659Z | B6: 1.0-dev | C6: Anna Beispiel | D6: Geändert | E6: Personenbezogene Daten | G6: Ja
A7: 2026-09-30T08:55:00.819Z | B7: 1.0-dev | C7: Anna Beispiel | D7: Geändert | E7: Vertraulichkeit · Gesetze & Verträge | G7: Normal
A8: 2026-09-30T08:55:00.869Z | B8: 1.0-dev | C8: Anna Beispiel | D8: Geändert | E8: Vertraulichkeit · Selbstbestimmung / DSGVO | G8: Normal
A9: 2026-09-30T08:55:00.920Z | B9: 1.0-dev | C9: Anna Beispiel | D9: Geändert | E9: Vertraulichkeit · Aufgabenerfüllung | G9: Normal
A10: 2026-09-30T08:55:00.969Z | B10: 1.0-dev | C10: Anna Beispiel | D10: Geändert | E10: Vertraulichkeit · Innen-/Außenwirkung | G10: Normal
A11: 2026-09-30T08:55:01.018Z | B11: 1.0-dev | C11: Anna Beispiel | D11: Geändert | E11: Vertraulichkeit · Finanzielle Auswirkungen | G11: Normal
A12: 2026-09-30T08:55:01.126Z | B12: 1.0-dev | C12: Anna Beispiel | D12: Geändert | E12: Integrität · Gesetze & Verträge | G12: Normal
A13: 2026-09-30T08:55:01.175Z | B13: 1.0-dev | C13: Anna Beispiel | D13: Geändert | E13: Integrität · Selbstbestimmung / DSGVO | G13: Normal
A14: 2026-09-30T08:55:01.227Z | B14: 1.0-dev | C14: Anna Beispiel | D14: Geändert | E14: Integrität · Leib & Leben | G14: Normal
... A23: 2026-09-30T08:55:01.745Z | B23: 1.0-dev | C23: Anna Beispiel | D23: Geändert | E23: Verfügbarkeit · Finanzielle Auswirkungen | G23: Normal
A24: 2026-09-30T08:55:01.904Z | B24: 1.0-dev | C24: Anna Beispiel | D24: Geändert | E24: Vertraulichkeit · Selbstbestimmung / DSGVO | F24: Normal | G24: Hoch
A25: 2026-09-30T08:55:01.906Z | B25: 1.0-dev | C25: Anna Beispiel | D25: Geändert | E25: Vertraulichkeit · Selbstbestimmung / DSGVO – Erläuterung | G25: Kontakt- und Vertragsdaten von ca. 120.000 Kund:innen; Meldepflicht nach Art. 33 DSGVO.
A26: 2026-09-30T08:55:02.481Z | B26: 1.0-dev | C26: Anna Beispiel | D26: Geändert | E26: Vertraulichkeit · Gesetze & Verträge | F26: Normal | G26: Hoch
A27: 2026-09-30T08:55:02.482Z | B27: 1.0-dev | C27: Anna Beispiel | D27: Geändert | E27: Vertraulichkeit · Gesetze & Verträge – Erläuterung | G27: Vertraulichkeitsvereinbarungen mit Großkunden sehen Vertragsstrafen vor.
A28: 2026-09-30T08:55:04.235Z | B28: 1.0-dev | C28: Anna Beispiel | D28: Geändert | E28: Verfügbarkeit · Aufgabenerfüllung | F28: Normal | G28: Sehr hoch
A29: 2026-09-30T08:55:04.236Z | B29: 1.0-dev | C29: Anna Beispiel | D29: Geändert | E29: Verfügbarkeit · Aufgabenerfüllung – Erläuterung | G29: Der Kundenservice arbeitet ausschließlich im CRM; tolerierbar ist höchstens eine Stunde.
A30: 2026-09-30T08:55:04.920Z | B30: 1.0-dev | C30: Anna Beispiel | D30: Geändert | E30: Vertraulichkeit – Begründung Schutzbedarf | G30: Umfangreiche personenbezogene Kundendaten mit vertraglichen Vertraulichkeitspflichten.
A31: 2026-09-30T08:55:04.927Z | B31: 1.0-dev | C31: Anna Beispiel | D31: Geändert | E31: Verfügbarkeit – Begründung Schutzbedarf | G31: Kernprozess Kundenservice ist vollständig vom CRM abhängig (RTO ≤ 1 h).
A32: 2026-09-30T08:55:05.833Z | B32: 1.0 | C32: Anna Beispiel | D32: Abgeschlossen | F32: 1.0-dev | G32: 1.0

Sheet Definitionen
A1: Szenario | B1: Schutzbedarfskategorie „normal“ | E1: Schutzbedarfskategorie „hoch“ | H1: Schutzbedarfskategorie „sehr hoch“
B2: Vertraulichkeit | C2: Integrität | D2: Verfügbarkeit | E2: Vertraulichkeit | F2: Integrität | G2: Verfügbarkeit | H2: Vertraulichkeit | I2: Integrität | J2: Verfügbarkeit
A3: Verstoß gegen Gesetze, Vorschriften und Verträge | B3: Gesetzliche/vertragliche Regelungen, die die Vertraulichkeit der Informationen fordern, sind entweder nicht existent oder die Kenntnisnahme der Informationen durch Unbefugte führt zu geringen Verstößen gegen gesetzliche/vertragliche Regelungen und damit zu geringfügigen juristischen Konsequenzen/Vertragsstrafen. | C3: Gesetzliche/vertragliche Regelungen, die die Integrität der Informationen fordern, sind entweder nicht existent oder die Verfälschung/Manipulation der Informationen führt zu geringen Verstößen gegen gesetzliche/vertragliche Regelungen und damit zu geringfügigen juristischen Konsequenzen/Vertragsstrafen. | D3: Gesetzliche/vertragliche Regelungen, die die Verfügbarkeit der Informationen fordern, sind entweder nicht existent oder die Nichtverfügbarkeit der Information (Ausfall der Anwendung oder Störung der Datenübertragung) führt nicht zur Nichteinhaltung zwingender Termine und damit zu geringfügigen juristischen Konsequenzen/Vertragsstrafen. | E3: Die Kenntnisnahme der Informationen durch Unbefugte führt zu erheblichen Verstößen gegen gesetzliche/vertragliche Regelungen und damit zu erheblichen juristischen Konsequenzen/Vertragsstrafen. | F3: Die Verfälschung/Manipulation der Informationen führt zu erheblichen Verstößen gegen gesetzliche/vertragliche Regelungen und damit zu erheblichen juristischen Konsequenzen/Vertragsstrafen. | G3: Die Nichtverfügbarkeit führt zu erheblichen Verstößen gegen gesetzliche/vertragliche Regelungen. Die Einhaltung zwingender Termine wird gefährdet; erhebliche juristische Konsequenzen/Vertragsstrafen können entstehen. | H3: Die Kenntnisnahme der Informationen durch Unbefugte führt zu fundamentalen Verstößen gegen gesetzliche/vertragliche Regelungen und damit zu massiven juristischen Konsequenzen/Vertragsstrafen. | I3: Die Verfälschung/Manipulation der Informationen führt zu fundamentalen Verstößen gegen gesetzliche/vertragliche Regelungen und damit zu massiven juristischen Konsequenzen/Vertragsstrafen. | J3: Die Nichtverfügbarkeit der Informationen führt zu fundamentalen Verstößen gegen gesetzliche/vertragliche Regelungen. Zwingend einzuhaltende Termine werden versäumt, massive juristische Konsequenzen/Vertragsstrafen können entstehen.
A4: Beeinträchtigung des informationellen Selbstbestimmungsrechts | B4: Es erfolgt keine Verarbeitung von personenbezogenen Daten oder die Kenntnisnahme der personenbezogenen Daten durch Unbefugte hat geringfügige Auswirkungen auf die Betroffenen und wird von diesen toleriert. | C4: Es erfolgt keine Verarbeitung von personenbezogenen Daten oder die Verfälschung/Manipulation personenbezogener Daten hat geringfügige Auswirkungen auf die Betroffenen und wird von diesen toleriert. | D4: Es erfolgt keine Verarbeitung von personenbezogenen Daten oder die Nichtverfügbarkeit personenbezogener Daten hat keine Auswirkungen auf die Betroffenen. | E4: Die Kenntnisnahme der personenbezogenen Daten durch Unbefugte hat erhebliche Auswirkungen auf die Betroffenen und kann sie in ihrer gesellschaftlichen Stellung oder ihren wirtschaftlichen Verhältnissen erheblich beeinträchtigen. Dies ist z. B. der Fall, wenn Informationen über den Gesundheitszustand oder die finanziellen Verhältnisse enthalten sind. | F4: Die Verfälschung/Manipulation personenbezogener Daten hat erhebliche Auswirkungen auf die Betroffenen und kann diese in ihrer gesellschaftlichen Stellung oder ihren wirtschaftlichen Verhältnissen erheblich beeinträchtigen. | G4: Die Nichtverfügbarkeit der Daten hat erhebliche Auswirkungen auf die Betroffenen und kann diese in ihrer gesellschaftlichen Stellung beeinträchtigen oder zu persönlichen oder wirtschaftlichen Nachteilen führen. Das ist z. B. der Fall, wenn durch Ausfall der Anwendung oder Störung der Datenübertragung personenbezogene Daten verloren gehen oder verfälscht werden. | H4: Die Kenntnisnahme der personenbezogenen Daten durch Unbefugte hat fundamentale Auswirkungen auf die Betroffenen und kann für diese eine Gefahr für Leib und Leben oder die persönliche Freiheit darstellen. Dies ist z. B. der Fall, wenn Daten von Personen mit speziellen Funktionen/Befugnissen durch Unbefugte zur Kenntnis genommen werden können. | I4: Die Verfälschung/Manipulation personenbezogener Daten hat fundamentale Auswirkungen auf die Betroffenen und kann für diese eine Gefahr für Leib und Leben oder die persönliche Freiheit darstellen. | J4: Die Nichtverfügbarkeit der Daten hat fundamentale Auswirkungen auf die Betroffenen und kann für diese eine Gefahr für Leib und Leben oder die persönliche Freiheit darstellen. Das ist z. B. der Fall, wenn durch Ausfall der Anwendung oder Störung der Datenübertragung personenbezogene Daten verloren gehen oder verfälscht werden.
A5: Beeinträchtigung der persönlichen Unversehrtheit | B5: Die Kenntnisnahme der Informationen durch Unbefugte führt nicht zu einer Beeinträchtigung der persönlichen Unversehrtheit. | C5: Die Verfälschung/Manipulation der Informationen oder Programmabläufe führt nicht zu einer Beeinträchtigung der persönlichen Unversehrtheit. | D5: Die Nichtverfügbarkeit der Informationen führt nicht zu einer Beeinträchtigung der persönlichen Unversehrtheit. | E5: Eine Beeinträchtigung der persönlichen Unversehrtheit durch Kenntnisnahme der Informationen durch Unbefugte kann nicht absolut ausgeschlossen werden. | F5: Eine Beeinträchtigung der persönlichen Unversehrtheit durch Verfälschung/Manipulation der Informationen oder Programmabläufe kann nicht absolut ausgeschlossen werden. | G5: Eine Beeinträchtigung der persönlichen Unversehrtheit durch Nichtverfügbarkeit der Informationen (Ausfall der Anwendung oder Störung der Datenübertragung) kann nicht absolut ausgeschlossen werden. | H5: Durch Kenntnisnahme der Informationen durch Unbefugte sind gravierende Beeinträchtigungen der persönlichen Unversehrtheit möglich. Es besteht Gefahr für Leib und Leben. | I5: Durch Verfälschung/Manipulation der Informationen oder Programmabläufe sind gravierende Beeinträchtigungen der persönlichen Unversehrtheit möglich. Es besteht Gefahr für Leib und Leben. | J5: Durch Ausfall der Anwendung / des IT-Systems oder Störung der Datenübertragung sind gravierende Beeinträchtigungen der persönlichen Unversehrtheit möglich. Es besteht Gefahr für Leib und Leben.
A6: Beeinträchtigung der Aufgabenerfüllung | B6: Die Vertraulichkeit der Informationen ist nicht Grundlage der Aufgabenerfüllung oder die Kenntnisnahme der Informationen durch Unbefugte hat geringfügige Auswirkungen auf die Aufgabenerfüllung und wird von den Betroffenen toleriert. | C6: Die Integrität der Informationen ist nicht Grundlage der Aufgabenerfüllung oder die Verfälschung/Manipulation der Informationen hat geringfügige Auswirkungen auf die Aufgabenerfüllung und wird von den Betroffenen toleriert. | D6: Die Verfügbarkeit der Informationen ist nicht Grundlage der Aufgabenerfüllung oder die Nichtverfügbarkeit der Informationen hat geringfügige Auswirkungen auf die Aufgabenerfüllung und wird auch bei einer Dauer über 24 Stunden hinaus von den Betroffenen toleriert. | E6: Die Vertraulichkeit der Informationen ist Grundlage der Aufgabenerfüllung; die Kenntnisnahme durch Unbefugte hat erhebliche Auswirkungen auf die Aufgabenerfüllung und wird von einzelnen Betroffenen als nicht tolerierbar eingeschätzt. | F6: Die Verfälschung/Manipulation der Informationen hat erhebliche Auswirkungen auf die Aufgabenerfüllung und wird von einzelnen Betroffenen als nicht tolerierbar eingeschätzt. | G6: Die Nichtverfügbarkeit der Informationen hat erhebliche Auswirkungen auf die Aufgabenerfüllung und kann nur bei einer Dauer zwischen 1 Stunde und 24 Stunden von den Betroffenen toleriert werden. | H6: Die Vertraulichkeit der Informationen ist Grundlage der Aufgabenerfüllung; die Kenntnisnahme durch Unbefugte hat fundamentale Auswirkungen auf die Aufgabenerfüllung und wird von allen Betroffenen als nicht tolerierbar eingeschätzt. | I6: Die Verfälschung/Manipulation der Informationen hat fundamentale Auswirkungen auf die Aufgabenerfüllung und wird von allen Betroffenen als nicht tolerierbar eingeschätzt. | J6: Die Nichtverfügbarkeit der Informationen hat fundamentale Auswirkungen auf die Aufgabenerfüllung und kann nur bis zu einer Dauer von 1 Stunde von den Betroffenen toleriert werden.
A7: Negative Innen- oder Außenwirkung | B7: Es erfolgt keine Verarbeitung von schutzbedürftigen Informationen oder die Kenntnisnahme der Informationen durch Unbefugte führt zu einer geringen bzw. nur ressortinternen Ansehens-/Vertrauensbeeinträchtigung. | C7: Es erfolgt keine Verarbeitung von schutzbedürftigen Informationen oder die Verfälschung/Manipulation der Informationen führt zu einer geringen bzw. nur ressortinternen Ansehens-/Vertrauensbeeinträchtigung. | D7: Es erfolgt keine Verarbeitung von schutzbedürftigen Informationen oder die Nichtverfügbarkeit der Informationen führt zu einer geringen bzw. nur ressortinternen Ansehens-/Vertrauensbeeinträchtigung. | E7: Die Kenntnisnahme der Informationen durch Unbefugte führt zu einer erheblichen Ansehens-/Vertrauensbeeinträchtigung auch außerhalb des Ressorts. | F7: Die Verfälschung/Manipulation der Informationen führt zu einer erheblichen Ansehens-/Vertrauensbeeinträchtigung auch außerhalb des Ressorts. | G7: Die Nichtverfügbarkeit der Informationen führt zu einer erheblichen Ansehens-/Vertrauensbeeinträchtigung auch außerhalb des Ressorts. | H7: Die Kenntnisnahme der Informationen durch Unbefugte führt zu einer dauerhaften Ansehens-/Vertrauensbeeinträchtigung außerhalb des Ressorts, ggf. sogar auf internationaler Ebene. | I7: Die Verfälschung/Manipulation der Informationen führt zu einer dauerhaften Ansehens-/Vertrauensbeeinträchtigung außerhalb des Ressorts, ggf. sogar auf internationaler Ebene. | J7: Die Nichtverfügbarkeit der Informationen führt zu einer dauerhaften Ansehens-/Vertrauensbeeinträchtigung außerhalb des Ressorts, ggf. sogar auf internationaler Ebene.
A8: Finanzielle Auswirkungen | B8: Es erfolgt keine Verarbeitung von schutzbedürftigen Informationen oder die Kenntnisnahme der Informationen durch Unbefugte hat geringfügige finanzielle Auswirkungen (Schaden unter 1.000.000 €). | C8: Es erfolgt keine Verarbeitung von schutzbedürftigen Informationen oder die Verfälschung/Manipulation der Informationen hat geringfügige finanzielle Auswirkungen (Schaden unter 1.000.000 €). | D8: Es erfolgt keine Verarbeitung von schutzbedürftigen Informationen oder die Nichtverfügbarkeit der Informationen hat geringfügige finanzielle Auswirkungen (Schaden unter 1.000.000 €). | E8: Die Kenntnisnahme der Informationen durch Unbefugte hat erhebliche finanzielle Auswirkungen (Schaden über 1.000.000 €). | F8: Die Verfälschung/Manipulation der Informationen hat erhebliche finanzielle Auswirkungen (Schaden über 1.000.000 €). | G8: Die Nichtverfügbarkeit der Informationen hat erhebliche finanzielle Auswirkungen (Schaden über 1.000.000 €). | H8: Die Kenntnisnahme der Informationen durch Unbefugte hat fundamentale finanzielle Auswirkungen (Schaden über 10.000.000 €). | I8: Die Verfälschung/Manipulation der Informationen hat fundamentale finanzielle Auswirkungen (Schaden über 10.000.000 €). | J8: Die Nichtverfügbarkeit der Informationen hat fundamentale finanzielle Auswirkungen (Schaden über 10.000.000 €).
A10: Maximumprinzip: Der Schutzbedarf eines Grundwerts entspricht der höchsten Einstufung aller Schadensszenarien. Kumulations-, Verteilungs- und Vererbungseffekte werden als manuelle Übersteuerung mit Begründung dokumentiert.

Sheet Hilfstabelle
A1: Grundwert: Vertraulichkeit | C1: Grundwert: Integrität | E1: Grundwert: Verfügbarkeit
A3: Spalte | B3: Wert | C3: Spalte | D3: Wert | E3: Spalte | F3: Wert
A4: G3 | B4: =IF(Anwendung!G3="Normal",1,(IF(Anwendung!G3="Hoch",10,(IF(Anwendung!G3="Sehr hoch",1000,0))))) -> 10 | C4: G39 | D4: =IF(Anwendung!G39="Normal",1,(IF(Anwendung!G39="Hoch",10,(IF(Anwendung!G39="Sehr hoch",1000,0))))) -> 1 | E4: G76 | F4: =IF(Anwendung!G76="Normal",1,(IF(Anwendung!G76="Hoch",10,(IF(Anwendung!G76="Sehr hoch",1000,0))))) -> 1
A5: G9 | B5: =IF(Anwendung!G9="Normal",1,(IF(Anwendung!G9="Hoch",10,(IF(Anwendung!G9="Sehr hoch",1000,0))))) -> 10 | C5: G45 | D5: =IF(Anwendung!G45="Normal",1,(IF(Anwendung!G45="Hoch",10,(IF(Anwendung!G45="Sehr hoch",1000,0))))) -> 1 | E5: G82 | F5: =IF(Anwendung!G82="Normal",1,(IF(Anwendung!G82="Hoch",10,(IF(Anwendung!G82="Sehr hoch",1000,0))))) -> 1
A6: G17 | B6: =IF(Anwendung!G17="Normal",1,(IF(Anwendung!G17="Hoch",10,(IF(Anwendung!G17="Sehr hoch",1000,0))))) -> 1 | C6: G51 | D6: =IF(Anwendung!G51="Normal",1,(IF(Anwendung!G51="Hoch",10,(IF(Anwendung!G51="Sehr hoch",1000,0))))) -> 1 | E6: G88 | F6: =IF(Anwendung!G88="Normal",1,(IF(Anwendung!G88="Hoch",10,(IF(Anwendung!G88="Sehr hoch",1000,0))))) -> 1
A7: G23 | B7: =IF(Anwendung!G23="Normal",1,(IF(Anwendung!G23="Hoch",10,(IF(Anwendung!G23="Sehr hoch",1000,0))))) -> 1 | C7: G54 | D7: =IF(Anwendung!G54="Normal",1,(IF(Anwendung!G54="Hoch",10,(IF(Anwendung!G54="Sehr hoch",1000,0))))) -> 1 | E7: G91 | F7: =IF(Anwendung!G91="Normal",1,(IF(Anwendung!G91="Hoch",10,(IF(Anwendung!G91="Sehr hoch",1000,0))))) -> 1000
A8: G29 | B8: =IF(Anwendung!G29="Normal",1,(IF(Anwendung!G29="Hoch",10,(IF(Anwendung!G29="Sehr hoch",1000,0))))) -> 1 | C8: G60 | D8: =IF(Anwendung!G60="Normal",1,(IF(Anwendung!G60="Hoch",10,(IF(Anwendung!G60="Sehr hoch",1000,0))))) -> 1 | E8: G97 | F8: =IF(Anwendung!G97="Normal",1,(IF(Anwendung!G97="Hoch",10,(IF(Anwendung!G97="Sehr hoch",1000,0))))) -> 1
C9: G66 | D9: =IF(Anwendung!G66="Normal",1,(IF(Anwendung!G66="Hoch",10,(IF(Anwendung!G66="Sehr hoch",1000,0))))) -> 1 | E9: G103 | F9: =IF(Anwendung!G103="Normal",1,(IF(Anwendung!G103="Hoch",10,(IF(Anwendung!G103="Sehr hoch",1000,0))))) -> 1
A10: Summe | B10: =SUM(B4:B8) -> 23 | C10: Summe | D10: =SUM(D4:D9) -> 6 | E10: Summe | F10: =SUM(F4:F9) -> 1005
