Workbook

Sheet Deckblatt
A1: Schutzbedarfsanalyse
H3: Speichern Sie jede Schutzbedarfsanalyse einzeln für jedes schutzbedürftiges Asset ab, um die Rückverfolgbarkeit zu gewährleisten!
A5: Schutzbedarfsfeststellung für | D5: hier das Asset eintragen
A7: Version: | D7: Versionsangabe
A9: Status: | D9: <bitte auswählen>
A11: zuletzt bearbeitet am: | D11: tt.mm.jjjj | F11: von:
A12: fachlich freigegeben am: | D12: tt.mm.jjjj | F12: von:
A13: freigegeben am: | D13: tt.mm.jjjj | F13: von:
A15: Verantwortliche Organisationseinheit:
A16: Kontakt:
A18: personenbezogene Daten: | D18: <bitte auswählen> | F18: besondere Art personenbezogener Daten: | I18: <bitte auswählen>
A20: Schutzbedarf Zusammenfassung | F20: Begründung
C21: Vertraulichkeit | D21: =Anwendung!E1 -> Sehr hoch
C22: Integrität | D22: =Anwendung!E37 -> Bitte Spalte E ausfüllen
C23: Verfügbarkeit | D23: =Anwendung!E74 -> Bitte Spalte E ausfüllen
A25: Änderungshistorie
A26: Nr. | B26: Version | D26: Datum | F26: Beschreibung der Änderung | I26: Bearbeiter
A27: 1
A28: 2
A29: 3
A30: 4
A31: 5
A32: 6
A33: 7
A34: 8
A35: 9
A36: 10

Sheet Anwendung
B1: Grundwert Vertraulichkeit | E1: =IF(Hilfstabelle!B10=5,"Normal", IF(Hilfstabelle!B10>=1000,"Sehr hoch",IF(Hilfstabelle!B10>=10,"Hoch","Bitte Spalte E ausfüllen"))) -> Sehr hoch
B2: Schadensszenario | D2: Frage | E2: Antwort | F2: weitere Ausführungen | G2: Schutzbedarf | H2: Erläuterung Schutzbedarf
B3: Verstoß gegen Gesetze, Vorschriften und Verträge | D3: Erfordern Gesetze, Vorschriften oder vertragliche Regelungen die Vertraulichkeit der Informationen? | E3: Ja | G3: =IF(AND(E5="Ja",E6="Ja",E7="Ja"),"Eingabe prüfen!",IF(AND(E5="Ja",E6="Ja"),"Eingabe prüfen!",IF(AND(E5="Ja",E7="Ja"),"Eingabe prüfen!",IF(AND(E6="Ja",E7="Ja"),"Eingabe prüfen!",IF(AND(E3="Nein",E5="Ja"),"Eingabe prüfen!",IF(AND(E3="Nein",E6="Ja"),"Eingabe prüfen!",IF(AND(E3="Nein",E7="Ja"),"Eingabe prüfen!",IF(AND(E3="Ja",E5="nein",E6="Nein",E7="Nein"),"Eingabe prüfen!",IF(OR(E3="Nein",E5="Ja"),"Normal",IF(E6="Ja","Hoch",IF(E7="Ja","Sehr hoch"))))))))))) -> Sehr hoch
D4: Falls ja, führt die Kenntnisnahme der Informationen durch Unbefugte zu
D5: geringen Verstößen gegen diese Regelungen und damit zu geringfügigen juristischen Konsequenzen / Vertragsstrafen?
D6: erheblichen Verstößen gegen diese Regelungen und damit zu erheblichen juristischen Konsequenzen / Vertragsstrafen?
D7: fundamentalen Verstößen gegen diese Regelungen und damit zu massiven juristischen Konsequenzen / Vertragsstrafen? | E7: Ja
B9: Beeinträchtigung des informationellen Selbstbestimmungs-rechts | D9: Erfolgt eine Verarbeitung von personenbezogenen Daten? | G9: =IF(AND(E11="Ja",E12="Ja",E13="Ja"),"Eingabe prüfen!",IF(AND(E11="Ja",E12="Ja"),"Eingabe prüfen!",IF(AND(E11="Ja",E13="Ja"),"Eingabe prüfen!",IF(AND(E12="Ja",E13="Ja"),"Eingabe prüfen!",IF(AND(E9="Nein",E11="Ja"),"Eingabe prüfen!",IF(AND(E9="Nein",E12="Ja"),"Eingabe prüfen!",IF(AND(E9="Nein",E13="Ja"),"Eingabe prüfen!",IF(AND(E9="Ja",E11="Nein",E12="Nein",E13="Nein"),"Eingabe prüfen!",IF(OR(E9="Nein",E11="Ja"),"Normal",IF(E12="Ja","Hoch",IF(E13="Ja","Sehr hoch"))))))))))) -> FALSE
D10: Falls ja, hat die Kenntnisnahme der personenbezogenen Daten durch Unbefugte
D11: geringfügige Auswirkungen auf die Betroffenen und wird von diesen toleriert?
D12: erhebliche Auswirkungen auf die Betroffenen und kann diese in ihrer gesellschaftlichen Stellung oder ihren wirtschaftlichen Verhältnissen erheblich beeinträchtigen?
D13: fundamentale Auswirkungen auf die Betroffenen und kann für diese eine Gefahr für Leib und Leben oder die persönliche Freiheit darstellen?
B15: Beeinträchtigung der persönlichen Unversehrtheit | D15: Eine Betrachtung dieses Szenarions beim Grundwert Vertraulichkeit ist nicht sinnvoll, da keine Unmittelbarkeit zwischen Vertraulichkeitsverlust und Beeinträchtigung denkbar ist.
B17: Beeinträchtigung der Aufgabenerfüllung | D17: Ist die Vertraulichkeit der Informationen Grundlage der Aufgabenerfüllung? | G17: =IF(AND(E19="Ja",E20="Ja",E21="Ja"),"Eingabe prüfen!",IF(AND(E19="Ja",E20="Ja"),"Eingabe prüfen!",IF(AND(E19="Ja",E21="Ja"),"Eingabe prüfen!",IF(AND(E20="Ja",E21="Ja"),"Eingabe prüfen!",IF(AND(E17="Nein",E19="Ja"),"Eingabe prüfen!",IF(AND(E17="Nein",E20="Ja"),"Eingabe prüfen!",IF(AND(E17="Nein",E21="Ja"),"Eingabe prüfen!",IF(AND(E17="Ja",E19="Nein",E20="Nein",E21="Nein"),"Eingabe prüfen!",IF(OR(E17="Nein",E19="Ja"),"Normal",IF(E20="Ja","Hoch",IF(E21="Ja","Sehr hoch"))))))))))) -> FALSE
D18: Falls ja, hat die Kenntnisnahme der Informationen durch Unbefugte
D19: geringfügige Auswirkungen auf die Aufgabenerfüllung und wird von diesen toleriert?
D20: erhebliche Auswirkungen auf die Aufgabenerfüllung und wird von einzelnen Betroffenen als nicht tolerierbar eingeschätzt?
D21: fundamentale Auswirkungen auf die Aufgabenerfüllung und wird von allen Betroffenen als nicht tolerierbar eingeschätzt?
B23: Negative Innen- oder Außenwirkung | D23: Erfolgt eine Verarbeitung schutzbedürftiger Informationen? | G23: =IF(AND(E25="Ja",E26="Ja",E27="Ja"),"Eingabe prüfen!",IF(AND(E25="Ja",E26="Ja"),"Eingabe prüfen!",IF(AND(E25="Ja",E27="Ja"),"Eingabe prüfen!",IF(AND(E26="Ja",E27="Ja"),"Eingabe prüfen!",IF(AND(E23="Nein",E25="Ja"),"Eingabe prüfen!",IF(AND(E23="Nein",E26="Ja"),"Eingabe prüfen!",IF(AND(E23="Nein",E27="Ja"),"Eingabe prüfen!",IF(AND(E23="Ja",E25="Nein",E26="Nein",E27="Nein"),"Eingabe prüfen!",IF(OR(E23="Nein",E25="Ja"),"Normal",IF(E26="Ja","Hoch",IF(E27="Ja","Sehr hoch"))))))))))) -> FALSE
D24: Falls ja, führt die Kenntnisnahme der Informationen durch Unbefugte zu
D25: einer geringen bzw. nur ressortinternen Ansehens- / Vertrauensbeeinträchtigung?
D26: einer erheblichen Ansehens- / Vertrauensbeeinträchtigung auch außerhalb des Ressorts?
D27: einer dauerhaften Ansehens- / Vertrauensbeeinträchtigung außerhalb des Ressorts, ggf. sogar auf internationaler Ebene?
B29: Finanzielle Auswirkungen | D29: Erfolgt eine Verarbeitung schutzbedürftiger Informationen? | G29: =IF(AND(E31="Ja",E32="Ja",E33="Ja"),"Eingabe prüfen!",IF(AND(E31="Ja",E32="Ja"),"Eingabe prüfen!",IF(AND(E31="Ja",E33="Ja"),"Eingabe prüfen!",IF(AND(E32="Ja",E33="Ja"),"Eingabe prüfen!",IF(AND(E29="Nein",E31="Ja"),"Eingabe prüfen!",IF(AND(E29="Nein",E32="Ja"),"Eingabe prüfen!",IF(AND(E29="Nein",E33="Ja"),"Eingabe prüfen!",IF(AND(E29="Ja",E31="Nein",E32="Nein",E33="Nein"),"Eingabe prüfen!",IF(OR(E29="Nein",E31="Ja"),"Normal",IF(E32="Ja","Hoch",IF(E33="Ja","Sehr hoch"))))))))))) -> FALSE
D30: Falls ja, führt die Kenntnisnahme der Informationen durch Unbefugte zu
D31: einem finanziellen Schaden von weniger als 1.000.000,00 €?
D32: einem finanziellen Schaden von mehr als 1.000.000,00 €?
D33: einem finanziellen Schaden von mehr als 10.000.000,00 €?
B37: Grundwert Integrität | E37: =IF(Hilfstabelle!D10=6,"Normal", IF(Hilfstabelle!D10>=1000,"Sehr hoch",IF(Hilfstabelle!D10>=10,"Hoch","Bitte Spalte E ausfüllen"))) -> Bitte Spalte E ausfüllen
B38: Schadensszenario | D38: Frage | E38: Antwort | F38: weitere Ausführungen | G38: Schutzbedarf | H38: Erläuterung Schutzbedarf
B39: Verstoß gegen Gesetze, Vorschriften und Verträge | D39: Erfordern Gesetze, Vorschriften oder vertragliche Regelungen die Integrität der Informationen? | G39: =IF(AND(E41="Ja",E42="Ja",E43="Ja"),"Eingabe prüfen!",IF(AND(E41="Ja",E42="Ja"),"Eingabe prüfen!",IF(AND(E41="Ja",E43="Ja"),"Eingabe prüfen!",IF(AND(E42="Ja",E43="Ja"),"Eingabe prüfen!",IF(AND(E39="Nein",E41="Ja"),"Eingabe prüfen!",IF(AND(E39="Nein",E42="Ja"),"Eingabe prüfen!",IF(AND(E39="Nein",E43="Ja"),"Eingabe prüfen!",IF(AND(E39="Ja",E41="Nein",E42="Nein",E43="Nein"),"Eingabe prüfen!",IF(OR(E39="Nein",E41="Ja"),"Normal",IF(E42="Ja","Hoch",IF(E43="Ja","Sehr hoch"))))))))))) -> FALSE
D40: Falls ja, führt die Verfälschung/Manipulation der Informationen zu
D41: geringen Verstößen gegen diese Regelungen und damit zu geringfügigen juristischen Konsequenzen / Vertragsstrafen?
D42: erheblichen Verstößen gegen diese Regelungen und damit zu erheblichen juristischen Konsequenzen / Vertragsstrafen?
D43: fundamentalen Verstößen gegen diese Regelungen und damit zu massiven juristischen Konsequenzen / Vertragsstrafen?
B45: Beeinträchtigung des informationellen Selbstbestimmungs-rechts | D45: Erfolgt eine Verarbeitung von personenbezogenen Daten? | G45: =IF(AND(E47="Ja",E48="Ja",E49="Ja"),"Eingabe prüfen!",IF(AND(E47="Ja",E48="Ja"),"Eingabe prüfen!",IF(AND(E47="Ja",E49="Ja"),"Eingabe prüfen!",IF(AND(E48="Ja",E49="Ja"),"Eingabe prüfen!",IF(AND(E45="Nein",E47="Ja"),"Eingabe prüfen!",IF(AND(E45="Nein",E48="Ja"),"Eingabe prüfen!",IF(AND(E45="Nein",E49="Ja"),"Eingabe prüfen!",IF(AND(E45="Ja",E47="Nein",E48="Nein",E49="Nein"),"Eingabe prüfen!",IF(OR(E45="Nein",E47="Ja"),"Normal",IF(E48="Ja","Hoch",IF(E49="Ja","Sehr hoch"))))))))))) -> FALSE
D46: Falls ja, hat die Verfälschung/Manipulation der personenbezogenen Daten
D47: geringfügige Auswirkungen auf die Betroffenen und wird von diesen toleriert?
D48: erhebliche Auswirkungen auf die Betroffenen und kann diese in ihrer gesellschaftlichen Stellung oder ihren wirtschaftlichen Verhältnissen erheblich beeinträchtigen?
D49: fundamentale Auswirkungen auf die Betroffenen und kann für diese eine Gefahr für Leib und Leben oder die persönliche Freiheit darstellen?
...

Sheet Schutzbedarfskategorien
A1: Schutzbedarfskategorie „normal“ | F1: Schutzbedarfskategorie "hoch" | I1: Schutzbedarfskategorie "sehr hoch"
A2: Szenario | B2: Vertraulichkeit | C2: Integrität | D2: Verfügbarkeit | E2: Szenario | F2: Vertraulichkeit | G2: Integrität | H2: Verfügbarkeit | I2: Vertraulichkeit | J2: Integrität | K2: Verfügbarkeit
A3: Verstoß gegen Gesetze, Verträge, Vorschriften | B3: Gesetzliche/vertragliche Regelungen, die die Vertraulichkeit, Integrität oder Verfügbarkeit der Informationen fordern, sind entweder nicht existent oder | E3: Verstoß gegen Gesetze, Verträge, Vorschriften | F3: Die Kenntnisnahme der Informationen durch Unbefugte führt zu erheblichen Verstößen gegen gesetzliche/vertragliche Regelungen und damit zu erheblichen juristischen Konsequenzen/Vertragsstrafen. | G3: Die Verfälschung/Manipulation der Informationen führt zu erheblichen Verstößen gegen gesetzliche/vertragliche Regelungen damit zu erheblichen juristischen Konsequenzen/Vertragsstrafen. | H3: Die Nichtverfügbarkeit führt zu erheblichen Verstößen gegen gesetzliche/vertragliche Regelungen. Die Einhaltung zwingender Termine wird gefährdet; erhebliche juristische Konsequenzen/Vertragsstrafen können entstehen. | I3: Die Kenntnisnahme der Informationen durch Unbefugte führt zu fundamentalen Verstößen gegen gesetzliche/vertragliche Regelungen und damit zu massiven juristischen Konsequenzen/Vertragsstrafen. | J3: Die Verfälschung/Manipulation der Informationen führt zu fundamentalen Verstößen gegen gesetzliche/vertragliche Regelungen und damit zu massiven juristischen Konsequenzen/Vertragsstrafen. | K3: Die Nichtverfügbarkeit der Informationen führt zu fundamentalen Verstößen gegen gesetzliche/vertragliche Regelungen. Zwingend einzuhaltende Termine werden versäumt, massive juristische Konsequenzen/Vertragsstrafen können entstehen.
B4: die Kenntnisnahme der Informationen durch Unbefugte führt zu geringen Verstößen gegen gesetzliche/vertragliche Regelungen und damit zu geringfügigen juristischen Konsequenzen/Vertragsstrafen. | C4: die Verfälschung/Manipulation der Informationen führt zu geringen Verstößen gegen gesetzliche/vertragliche Regelungen und damit zu geringfügigen juristischen Konsequenzen/Vertragsstrafen. | D4: die Nichtverfügbarkeit der Information (Ausfall der Anwendung oder Störung der Datenübertragung) führt nicht zur Nichteinhaltung zwingender Termine und damit zu geringfügigen juristischen Konsequenzen/Vertragsstrafen.
A5: Beeinträchtigung des informationellen Selbst-bestimmungsrechts | B5: Es erfolgt keine Verarbeitung von personenbezogenen Daten oder | E5: Beeinträchtigung des informationellen Selbst-bestimmungsrechts | F5: Die Kenntnisnahme der personenbezogenen Daten durch Unbefugte hat erhebliche Auswirkungen auf die Betroffenen und kann sie in ihrer gesellschaftlichen Stellung oder ihren wirtschaftlichen Verhältnissen erheblich beeinträchtigen. Dies ist z. B. der Fall, wenn Informationen über den Gesundheitszustand oder die finanziellen Verhältnisse enthalten sind. | G5: Die Verfälschung/Manipulation personenbezogener Daten hat erhebliche Auswirkungen auf die Betroffenen und kann diese in ihrer gesellschaftlichen Stellung oder ihren wirtschaftlichen Verhältnissen erheblich beeinträchtigen. | H5: Die Nichtverfügbarkeit der Daten hat erhebliche Auswirkungen auf die Betroffenen und kann diese in ihrer gesellschaftlichen Stellung beeinträchtigen oder zu persönlichen oder wirtschaftlichen Nachteilen führen. Das ist z.B. der Fall, wenn durch Ausfall der Anwendung oder Störung der Datenübertragung personenbezogene Daten verloren gehen oder verfälscht werden. | I5: Die Kenntnisnahme der personenbezogenen Daten durch Unbefugte hat fundamentale Auswirkungen auf die Betroffenen und kann für diese eine Gefahr für Leib und Leben oder die persönliche Freiheit darstellen. Dies ist z. B. der Fall, wenn Daten von Personen mit speziellen Funktionen/Befugnissen durch Unbefugte zur Kenntnis genommen werden können. | J5: Die Verfälschung/Manipulation personenbezogener Daten hat fundamentale Auswirkungen auf die Betroffenen und kann für diese eine Gefahr für Leib und Leben oder die persönliche Freiheit darstellen. | K5: Die Nichtverfügbarkeit der Daten hat fundamentale Auswirkungen auf die Betroffenen und kann für diese eine Gefahr für Leib und Leben oder die persönliche Freiheit darstellen. Das ist z.B. der Fall, wenn durch Ausfall der Anwendung oder Störung der Datenübertragung personenbezogene Daten verloren gehen oder verfälscht werden.
B6: die Kenntnisnahme der personenbezogenen Daten durch Unbefugte hat geringfügige Auswirkungen auf die Betroffenen und wird von diesen toleriert. | C6: die Verfälschung/Manipulation personenbezogener Daten hat geringfügige Auswirkungen auf die Betroffenen und wird von diesen toleriert. | D6: die Nichtverfügbarkeit personenbezogener Daten hat keine Auswirkungen auf die Betroffenen.
A7: Beeinträchtigung der persönlichen Unversehrtheit | B7: Die Kenntnisnahme der Informationen durch Unbefugte führt nicht zu einer Beeinträchtigung der persönlichen Unversehrtheit. | C7: Die Verfälschung/Manipulation der Informationen oder Programmabläufe führt nicht zu einer Beeinträchtigung der persönlichen Unversehrtheit. | D7: Die Nichtverfügbarkeit der Informationen führt nicht zu einer Beeinträchtigung der persönlichen Unversehrtheit. | E7: Beeinträchtigung der persönlichen Unversehrtheit | F7: Eine Beeinträchtigung der persönlichen Unversehrtheit durch Kenntnisnahme der Informationen durch Unbefugte kann nicht absolut ausgeschlossen werden. | G7: Eine Beeinträchtigung der persönlichen Unversehrtheit durch Verfälschung/Manipulation der Informationen oder kann nicht absolut ausgeschlossen werden. | H7: Eine Beeinträchtigung der persönlichen Unversehrtheit durch Nichtverfügbarkeit der Informationen (Ausfall der Anwendung oder Störung der Datenübertragung) kann nicht absolut ausgeschlossen werden. | I7: Durch Kenntnisnahme der Informationen durch Unbefugte sind gravierende Beeinträchtigungen der persönlichen Unversehrtheit möglich. Es besteht Gefahr für Leib und Leben. | J7: Durch Verfälschung/Manipulation der Informationen oder Programmabläufe sind gravierende Beeinträchtigungen der persönlichen Unversehrtheit möglich. Es besteht Gefahr für Leib und Leben. | K7: Durch Ausfall der Anwendung / des IT-Systems oder Störung der Datenübertragung sind gravierende Beeinträchtigungen der persönlichen Unversehrtheit möglich. Es besteht Gefahr für Leib und Leben.
A8: Beeinträchtigung der Aufgabenerfüllung | B8: Die Vertraulichkeit der Informationen ist nicht Grundlage der Aufgabenerfüllung oder | E8: Beeinträchtigung der Aufgabenerfüllung | F8: Die Vertraulichkeit der Informationen ist Grundlage der Aufgabenerfüllung; die Kenntnisnahme durch Unbefugte hat erhebliche Auswirkungen auf die Aufgabenerfüllung und wird von einzelnen Betroffenen als nicht tolerierbar eingeschätzt. | G8: Die Verfälschung/Manipulation der Informationen hat erhebliche Auswirkungen auf die Aufgabenerfüllung und wird von einzelnen Betroffenen als nicht tolerierbar eingeschätzt. | H8: Die Nichtverfügbarkeit der Informationen hat erhebliche Auswirkungen auf die Aufgabenerfüllung und kann nur bei einer Dauer zwischen einer und 24 Stunden von den Betroffenen toleriert werden. | I8: Die Vertraulichkeit der Informationen ist Grundlage der Aufgabenerfüllung; die Kenntnisnahme durch Unbefugte hat fundamentale Auswirkungen auf die Aufgabenerfüllung und wird von allen Betroffenen als nicht tolerierbar eingeschätzt. | J8: Die Verfälschung/Manipulation der Informationen hat fundamentale Auswirkungen auf die Aufgabenerfüllung und wird von allen Betroffenen als nicht tolerierbar eingeschätzt. | K8: Die Nichtverfügbarkeit der Informationen hat fundamentale Auswirkungen auf die Aufgabenerfüllung und kann nur bis zu einer Dauer von 1 Stunde von den Betroffenen toleriert werden.
B9: die Kenntnisnahme der Informationen durch Unbefugte hat geringfügige Auswirkungen auf die Aufgabenerfüllung und wird von den Betroffenen toleriert. | C9: die Verfälschung/Manipulation der Informationen hat geringfügige Auswirkungen auf die Aufgabenerfüllung und wird von den Betroffenen bemerkt werden. | D9: die Nichtverfügbarkeit der Informationen hat geringfügige Auswirkungen auf die Aufgabenerfüllung und wird auch bei einer Dauer über 24 Stunden hinaus von den Betroffenen toleriert.
A10: Negative Innen- und Außenwirkung | B10: Es erfolgt keine Verarbeitung von schutzbedürftigen Informationen oder | E10: Negative Innen- und Außenwirkung | F10: Die Kenntnisnahme der Informationen durch Unbefugte führt zu einer erheblichen Ansehens-/ Vertrauensbeeinträchtigung auch außerhalb des Ressorts. | G10: Die Verfälschung/Manipulation der Informationen führt zu einer erheblichen Ansehens-/ Vertrauensbeeinträchtigung auch außerhalb des Ressorts. | H10: Die Nichtverfügbarkeit der Informationen führt zu einer erheblichen Ansehens-/Vertrauensbeeinträchtigung auch außerhalb der Ressorts. | I10: Die Kenntnisnahme der Informationen durch Unbefugte führt zu einer dauerhaften Ansehens-/ Vertrauensbeeinträchtigung außerhalb des Ressorts, ggf. sogar auf internationaler Ebene. | J10: Die Verfälschung/Manipulation der Informationen führt zu einer dauerhaften Ansehens-/ Vertrauensbeeinträchtigung außerhalb des Ressorts, ggf. sogar auf internationaler Ebene. | K10: Die Nichtverfügbarkeit der Informationen führt zu einer dauerhaften Ansehens-/ Vertrauensbeeinträchtigung außerhalb des Ressorts, ggf. sogar auf internationaler Ebene.
B11: die Kenntnisnahme der Informationen durch Unbefugte führt zu einer geringen bzw. nur ressortinternen Ansehens-/Vertrauensbeeinträchtigung. | C11: die Verfälschung/Manipulation der Informationen führt zu einer geringen bzw. nur ressortinternen Ansehens-/Vertrauensbeeinträchtigung | D11: die Nichtverfügbarkeit der Informationen führt zu einer geringen bzw. nur ressortinternen Ansehens-/Vertrauensbeeinträchtigung.
A12: Finanzielle Auswirkungen | B12: Es erfolgt keine Verarbeitung von schutzbedürftigen Informationen oder | E12: Finanzielle Auswirkungen | F12: Die Kenntnisnahme der Informationen durch Unbefugtehat erhebliche finanzielle Auswirkungen. Das ist der Fall, wenn der finanzielle Schaden eine Höhe von mehr als 1.000.000 € hat. | G12: Die Verfälschung/Manipulation der Informationen hat erhebliche finanzielle Auswirkungen. Das ist der Fall, wenn der finanzielle Schaden eine Höhe von mehr als 1.000.000 € hat. | H12: Die Nichtverfügbarkeit der Informationen hat erhebliche finanzielle Auswirkungen. Das ist der Fall, wenn der finanzielle Schaden eine Höhe von mehr als 1.000.000 € hat. | I12: Die Kenntnisnahme der Informationen durch Unbefugte hat fundamentale finanzielle Ausirkungen. Das ist der Fall, wenn der finanzielle Schaden eine Höhe von mehr als 10.000.000 € hat. | J12: Die Verfälschung/Manipulation der Informationen hat fundamentale finanzielle Auswirkungen. Das ist der Fall, wenn der finanzielle Schaden eine Höhe von mehr als 10.000.000 € hat. | K12: Die Nichtverfügbarkeit der Informationen hat fundamentale finanzielle Auswirkungen. Das ist der Fall, wenn der finanzielle Schaden eine Höhe von mehr als 10.000.000 € hat.
B13: die Kenntnisnahme der Informationen durch Unbefugte hat geringfügige finanzielle Auswirkungen. Das ist der Fall, wenn der finanziellen Schaden eine Höhe von weniger als 1.000.000 € hat. | C13: die Verfälschung/Manipulation der Informationen hat geringfügige finanzielle Auswirkungen. Das ist der Fall, wenn der finanzielle Schaden eine Höhe von weniger als 1.000.000 € hat. | D13: die Nichtverfügbarkeit der Informationen hat geringfügige finanzielle Auswirkungen. Das ist der Fall, wenn der finanzielle Schaden eine Höhe von weniger als 1.000.000 € hat.

Sheet Hilfstabelle
A1: Grundwert: Vertraulichkeit | C1: Grundwert: Integrität | E1: Grundwert: Verfügbarkeit
A3: Spalte | B3: Wert | C3: Spalte | D3: Wert | E3: Spalte | F3: Wert
A4: G3 | B4: =IF(Anwendung!G3="Normal",1,(IF(Anwendung!G3="Hoch",10,(IF(Anwendung!G3="Sehr hoch",1000,0))))) -> 1000 | C4: G39 | D4: =IF(Anwendung!G39="Normal",1,(IF(Anwendung!G39="Hoch",10,(IF(Anwendung!G39="Sehr hoch",1000,0))))) -> 0 | E4: G76 | F4: =IF(Anwendung!G76="Normal",1,(IF(Anwendung!G76="Hoch",10,(IF(Anwendung!G76="Sehr hoch",1000,0))))) -> 0
A5: G9 | B5: =IF(Anwendung!G9="Normal",1,(IF(Anwendung!G9="Hoch",10,(IF(Anwendung!G9="Sehr hoch",1000,0))))) -> 0 | C5: G45 | D5: =IF(Anwendung!G45="Normal",1,(IF(Anwendung!G45="Hoch",10,(IF(Anwendung!G45="Sehr hoch",1000,0))))) -> 0 | E5: G82 | F5: =IF(Anwendung!G82="Normal",1,(IF(Anwendung!G82="Hoch",10,(IF(Anwendung!G82="Sehr hoch",1000,0))))) -> 0
A6: G17 | B6: =IF(Anwendung!G17="Normal",1,(IF(Anwendung!G17="Hoch",10,(IF(Anwendung!G17="Sehr hoch",1000,0))))) -> 0 | C6: G51 | D6: =IF(Anwendung!G51="Normal",1,(IF(Anwendung!G51="Hoch",10,(IF(Anwendung!G51="Sehr hoch",1000,0))))) -> 0 | E6: G88 | F6: =IF(Anwendung!G88="Normal",1,(IF(Anwendung!G88="Hoch",10,(IF(Anwendung!G88="Sehr hoch",1000,0))))) -> 0
A7: G23 | B7: =IF(Anwendung!G23="Normal",1,(IF(Anwendung!G23="Hoch",10,(IF(Anwendung!G23="Sehr hoch",1000,0))))) -> 0 | C7: G54 | D7: =IF(Anwendung!G54="Normal",1,(IF(Anwendung!G54="Hoch",10,(IF(Anwendung!G54="Sehr hoch",1000,0))))) -> 0 | E7: G91 | F7: =IF(Anwendung!G91="Normal",1,(IF(Anwendung!G91="Hoch",10,(IF(Anwendung!G91="Sehr hoch",1000,0))))) -> 0
A8: G29 | B8: =IF(Anwendung!G29="Normal",1,(IF(Anwendung!G29="Hoch",10,(IF(Anwendung!G29="Sehr hoch",1000,0))))) -> 0 | C8: G60 | D8: =IF(Anwendung!G60="Normal",1,(IF(Anwendung!G60="Hoch",10,(IF(Anwendung!G60="Sehr hoch",1000,0))))) -> 0 | E8: G97 | F8: =IF(Anwendung!G97="Normal",1,(IF(Anwendung!G97="Hoch",10,(IF(Anwendung!G97="Sehr hoch",1000,0))))) -> 0
C9: G66 | D9: =IF(Anwendung!G66="Normal",1,(IF(Anwendung!G66="Hoch",10,(IF(Anwendung!G66="Sehr hoch",1000,0))))) -> 0 | E9: G103 | F9: =IF(Anwendung!G103="Normal",1,(IF(Anwendung!G103="Hoch",10,(IF(Anwendung!G103="Sehr hoch",1000,0))))) -> 0
A10: Summe | B10: =SUM(B4:B8) -> 1000 | C10: Summe | D10: =SUM(D4:D9) -> 0 | E10: Summe | F10: =SUM(F4:F9) -> 0
